<robot name="robo_seeker"
    xmlns:xacro="http://www.ros.org/wiki/xacro">

    <link name="robot_footprint"></link>

    <link name='chassis'>
        <inertial>
            <mass value="15.0"/>
            <origin xyz="0.0 0 0" rpy=" 0 0 0"/>
            <inertia ixx="0.1" ixy="0" ixz="0" iyy="0.1" iyz="0" izz="0.1" />
        </inertial>
        <collision name='collision'>
            <origin xyz="0 0 0" rpy=" 0 0 0"/>
            <geometry>
                <box size=".4 .2 .1"/>
            </geometry>
        </collision>
        <visual name='chassis_visual'>
            <origin xyz="0 0 0" rpy=" 0 0 0"/>
            <geometry>
                <box size=".4 .2 .1"/>
            </geometry>
            <material name="blue">
                <color rgba="0 0 1 1"/>
            </material>
        </visual>
        <collision name='back_caster_collision'>
            <origin xyz="-0.15 0 -0.05" rpy=" 0 0 0"/>
            <geometry>
                <sphere radius="0.0499"/>
            </geometry>
        </collision>
        <visual name='back_caster_visual'>
            <origin xyz="-0.15 0 -0.05" rpy=" 0 0 0"/>
            <geometry>
                <sphere radius="0.05"/>
            </geometry>
        </visual>
        <collision name='front_caster_collision'>
            <origin xyz="0.15 0 -0.05" rpy=" 0 0 0"/>
            <geometry>
                <sphere radius="0.0499"/>
            </geometry>
        </collision>

        <visual name='front_caster_visual'>
            <origin xyz="0.15 0 -0.05" rpy=" 0 0 0"/>
            <geometry>
                <sphere radius="0.05"/>
            </geometry>
        </visual>
    </link>

    <link name="right_wheel_link">
        <visual>
            <origin xyz="0 0 0" rpy=" 0 1.5707 1.5707"/>
            <geometry>
                <cylinder radius="0.1" length="0.05"/>
            </geometry>
            <material name="red">
                <color rgba="1 0 0 1"/>
            </material>
        </visual>
        <collision>
            <origin xyz="0 0 0" rpy=" 0 1.5707 1.5707"/>
            <geometry>
                <cylinder radius="0.1" length="0.05"/>
            </geometry>
        </collision>
        <inertial>
            <mass value="5.0"/>
            <origin xyz="0 0 0" rpy=" 0 1.5707 1.5707"/>
            <inertia ixx="0.1" ixy="0" ixz="0" iyy="0.1" iyz="0" izz="0.1" />
        </inertial>
    </link>

    <link name="left_wheel_link">
        <visual>
            <origin xyz="0 0 0" rpy=" 0 1.5707 1.5707"/>
            <geometry>
                <cylinder radius="0.1" length="0.05"/>
            </geometry>
            <material name="red"/>
        </visual>
        <collision>
            <origin xyz="0 0 0" rpy=" 0 1.5707 1.5707"/>
            <geometry>
                <cylinder radius="0.1" length="0.05"/>
            </geometry>
        </collision>
        <inertial>
            <mass value="5.0"/>
            <origin xyz="0 0 0" rpy=" 0 1.5707 1.5707"/>
            <inertia ixx="0.1" ixy="0" ixz="0" iyy="0.1" iyz="0" izz="0.1" />
        </inertial>
    </link>

    <link name="camera">
        <visual>
            <origin xyz="0 0 0" rpy=" 0 0 0"/>
            <geometry>
                <box size="0.05 0.05 0.05"/>
            </geometry>
            <material name="green">
                <color rgba="0 1 0 1"/>
            </material>
        </visual>
        <collision>
            <origin xyz="0 0 0" rpy=" 0 0 0"/>
            <geometry>
                <box size="0.05 0.05 0.05"/>
            </geometry>
        </collision>
        <inertial>
            <mass value="0.1"/>
            <origin xyz="0 0 0" rpy=" 0 0 0"/>
            <inertia ixx="1e-6" ixy="0" ixz="0" iyy="1e-6" iyz="0" izz="1e-6" />
        </inertial>
    </link>

    <link name="hokuyo">
        <visual>
            <origin xyz="0 0 0" rpy=" 0 0 0"/>
            <geometry>
                <mesh filename="package://ball_chaser_description/meshes/hokuyo.dae"/>
            </geometry>
        </visual>
        <collision>
            <origin xyz="0 0 0.0" rpy=" 0 0 0"/>
            <geometry>
                <box size="0.1 0.1 0.1"/>
            </geometry>
        </collision>
        <inertial>
            <mass value="1e-5"/>
            <origin xyz="0 0 0.0" rpy=" 0 0 0"/>
            <inertia ixx="1e-6" ixy="0" ixz="0" iyy="1e-6" iyz="0" izz="1e-6" />
        </inertial>
    </link>

    <joint name="robot_footprint_joint" type="fixed">
        <origin xyz="0 0 0" rpy="0 0 0" />
        <parent link="robot_footprint"/>
        <child link="chassis" />
    </joint>

    <joint type="continuous" name="right_wheel_hinge">
        <origin xyz="0 0.125 0" rpy="0 0 0"/>
        <child link="right_wheel_link"/>
        <parent link="chassis"/>
        <axis xyz="0 1 0" rpy="0 0 0"/>
        <limit effort="10000" velocity="1000"/>
        <dynamics damping="1.0" friction="1.0"/>
    </joint>

    <joint type="continuous" name="left_wheel_hinge">
        <origin xyz="0 -0.125 0" rpy="0 0 0"/>
        <child link="left_wheel_link"/>
        <parent link="chassis"/>
        <axis xyz="0 1 0" rpy="0 0 0"/>
        <limit effort="10000" velocity="1000"/>
        <dynamics damping="1.0" friction="1.0"/>
    </joint>

    <joint type="fixed" name="camera_joint">
        <origin xyz="0.2 0 0" rpy="0 0 0"/>
        <child link="camera"/>
        <parent link="chassis"/>
        <axis xyz="0 1 0" rpy="0 0 0"/>
    </joint>

    <joint type="fixed" name="hokuyo_joint">
        <origin xyz="0.15 0 0.1" rpy="0 0 0"/>
        <child link="hokuyo"/>
        <parent link="chassis"/>
        <axis xyz="0 1 0" rpy="0 0 0"/>
    </joint>

    <gazebo reference="chassis">
        <material>Gazebo/Blue</material>
    </gazebo>

    <gazebo reference="right_wheel_link">
        <material>Gazebo/Grey</material>
    </gazebo>

    <gazebo reference="left_wheel_link">
        <material>Gazebo/Grey</material>
    </gazebo>


    <gazebo>
        <plugin name="gazebo_ros_diff_drive" filename="libgazebo_ros_diff_drive.so">

            <update_rate>10</update_rate>


            <left_joint>left_wheel_hinge</left_joint>
            <right_joint>right_wheel_hinge</right_joint>

            <!-- kinematics -->
            <wheel_separation>0.4</wheel_separation>
            <wheel_diameter>0.2</wheel_diameter>

            <!-- output -->
            <publish_odom>true</publish_odom>
            <publish_odom_tf>true</publish_odom_tf>
            <publish_wheel_tf>true</publish_wheel_tf>

            <odometry_topic>odom</odometry_topic>
            <odometry_frame>odom</odometry_frame>
            <robot_base_frame>robot_footprint</robot_base_frame>

        </plugin>
    </gazebo>

    <gazebo reference="camera">
        <material>Gazebo/Grey</material>
        <sensor name="camera" type="camera">
            <pose>0 0 0 0 0 0</pose>
            <visualize>true</visualize>
            <update_rate>10.0</update_rate>
            <camera name="realsense_depth_camera">
                <horizontal_fov>1.46608</horizontal_fov>
                <image>
                    <width>800</width>
                    <height>800</height>
                    <format>R8G8B8</format>
                </image>
                <clip>
                    <near>0.02</near>
                    <far>300</far>
                </clip>
            </camera>
            <plugin name="camera_controller" filename="libgazebo_ros_camera.so">
                <ros>
                    <namespace>ball_chaser</namespace>
                    <remapping>image_raw:=camera_img</remapping>
                </ros>
                <frame_name>camera</frame_name>
                <hack_baseline>0.07</hack_baseline>
                <min_depth>0.05</min_depth>
                <max_depth>8.0</max_depth>
            </plugin>
        </sensor>
    </gazebo>

    <!-- hokuyo -->
    <gazebo reference="hokuyo">
        <sensor type="ray" name="head_hokuyo_sensor">
            <pose>0 0 0 0 0 0</pose>
            <visualize>false</visualize>
            <update_rate>40</update_rate>
            <ray>
                <scan>
                    <horizontal>
                        <samples>720</samples>
                        <resolution>1</resolution>
                        <min_angle>-1.570796</min_angle>
                        <max_angle>1.570796</max_angle>
                    </horizontal>
                </scan>
                <range>
                    <min>0.10</min>
                    <max>30.0</max>
                    <resolution>0.01</resolution>
                </range>
                <noise>
                    <type>gaussian</type>
                    <mean>0.0</mean>
                    <stddev>0.01</stddev>
                </noise>
            </ray>
            <plugin name="robo_seeker_laserscan" filename="libgazebo_ros_ray_sensor.so">
                <ros>
                    <remapping>~/out:=scan</remapping>
                </ros>
                <output_type>sensor_msgs/LaserScan</output_type>
                <frame_name>hokuyo</frame_name>
            </plugin>
        </sensor>
    </gazebo>


</robot>